Workbook

Sheet Start Here
B2: Holiday Hosting Planner
B3: Guest count in → food, drinks, shopping list, budget and cooking schedule out.
B5: Your party at a glance
B6: Event | C6: =Setup!$C$6 -> Thanksgiving Dinner | E6: Estimated shopping | F6: =Shopping!$C$6 -> 308.39327
B7: Date | C7: =Setup!$C$7 -> 46352 | E7: Budget left | F7: =Budget!$C$18 -> 196.60673
B8: Dinner is served | C8: =Setup!$C$8 -> 0.70833333 | E8: Turkey goes in the oven | F8: =IF(Food!$J$9=0,"—",Timeline!$H$9) -> 0.50694444
B9: Guests | C9: =Setup!$C$26&" adults, "&Setup!$C$27&" kids" -> 10 adults, 2 kids | E9: Start thawing turkey | F9: =Timeline!$C$24 -> 46347
B10: Food to buy | C10: =TEXT(Food!$H$39,"0.0")&" kg / "&TEXT(Food!$H$39*2.2046,"0.0")&" lb" -> 17.7 kg / 39.1 lb | E10: Checklist | F10: =Checklist!C4 -> 0 of 23 tasks done
B13: How to use it (3 steps)
B14: 1. Setup tab — type your date, dinner time and number of guests (gold cells).
B15: 2. Food tab — set Include? to Yes for the dishes on your menu. Quantities appear instantly.
B16: 3. Shopping tab — add your store's prices, then tick items off as you buy them. Budget, Timeline and Checklist update by themselves.
B18: Colour guide
B19: Gold cell | C19: Type or pick here
B20: White cell | C20: Calculated for you — no need to touch
B22: What's inside
B23: Setup | C23: Date, time, guests, appetite, leftovers, units, budget
B24: Guests | C24: RSVPs, diets, allergies, who brings what, seating
B25: Food | C25: 25 holiday dishes + your own, per-person portions → exact kg / lb
B26: Drinks | C26: Wine, beer, spirits, soft drinks, water, ice
B27: Shopping | C27: Auto-filled list with prices and a bought ✓
B28: Budget | C28: Planned vs. actual, cost per guest
B29: Timeline | C29: When to start each dish + turkey thaw date
B30: Checklist | C30: 3 weeks out → party day, tick as you go
B32: Works in Microsoft Excel and Google Sheets (File → Import, or upload to Google Drive and open with Google Sheets). Portions are rules of thumb — trust your crowd.

Sheet Setup
B2: Setup
B3: Fill in the gold cells. Everything else in the planner updates automatically.
B5: Your event
B6: Event name | C6: Thanksgiving Dinner | D6: Any name — shows on the Start Here page.
B7: Event date | C7: 46352 | D7: Used for the turkey-thawing and shopping reminders.
B8: Dinner is served at | C8: 0.70833333 | D8: The cooking timeline counts backwards from this time.
B9: Party length (hours) | C9: 5 | D9: Drives the drinks calculation.
B10: Guest count from | C10: Manual | D10: Manual = use the two numbers below. Guest List = count confirmed (RSVP Yes) guests on the Guests tab.
B11: Adults (manual) | C11: 10 | D11: Teens 12+ count as adults.
B12: Kids under 12 (manual) | C12: 2 | D12: Kids eat about half an adult portion (editable below).
B13: Appetite of the crowd | C13: Normal | D13: Light = -15%, Normal, Hearty = +20% food.
B14: Want leftovers? | C14: Yes | D14: Yes adds 25% to all food so everyone takes a plate home.
B15: Units for shopping | C15: Imperial (lb) | D15: Imperial (lb, qt) or Metric (kg, L). Both are always shown on the Food tab.
B16: Share of adults who drink alcohol | C16: 0.75 | D16: Non-drinkers and kids get extra soft drinks instead.
B17: Total budget | C17: 600 | D17: In your own currency. Tracked on the Budget tab.
B19: Portion assumptions (change only if you want to)
B20: Kid portion vs. adult | C20: 0.5 | D20: Common catering rule of thumb: a child under 12 eats about half an adult portion.
B21: Extra food for leftovers | C21: 0.25 | D21: Applied only when 'Want leftovers?' is Yes.
B22: Light appetite adjustment | C22: 0.85 | D22: Multiplier on every portion.
B23: Hearty appetite adjustment | C23: 1.2 | D23: Multiplier on every portion.
B25: Calculated (do not edit)
B26: Adults used | C26: =IF(Setup!$C$10="Guest List",Guests!$I$6,Setup!$C$11) -> 10
B27: Kids used | C27: =IF(Setup!$C$10="Guest List",Guests!$I$7,Setup!$C$12) -> 2
B28: Total guests | C28: =Setup!$C$26+Setup!$C$27 -> 12
B29: Appetite multiplier | C29: =IF(Setup!$C$13="Light",Setup!$C$22,IF(Setup!$C$13="Hearty",Setup!$C$23,1)) -> 1
B30: Leftover multiplier | C30: =IF(Setup!$C$14="Yes",1+Setup!$C$21,1) -> 1.25
B31: Portion factor (adult portions to cook) | C31: =(Setup!$C$26+Setup!$C$27*Setup!$C$20)*Setup!$C$29*Setup!$C$30 -> 13.75
B32: Metric units? (1 = yes) | C32: =IF(LEFT(Setup!$C$15,6)="Metric",1,0) -> 0

Sheet Guests
B2: Guest List
B3: Track RSVPs, diets and allergies. Set Setup → 'Guest count from' to Guest List to use these numbers.
C5: Waiting for reply | D5: =COUNTIF($E$10:$E$69,"Maybe")+COUNTIFS($C$10:$C$69,"<>",$E$10:$E$69,"") -> 1 | H5: Summary
C6: Special diets | D6: =COUNTIFS($F$10:$F$69,"<>None",$F$10:$F$69,"<>",$E$10:$E$69,"Yes") -> 1 | H6: Confirmed adults | I6: =COUNTIFS($D$10:$D$69,"Adult",$E$10:$E$69,"Yes") -> 2
C7: Not coming | D7: =COUNTIF($E$10:$E$69,"No") -> 0 | H7: Confirmed kids | I7: =COUNTIFS($D$10:$D$69,"Kid",$E$10:$E$69,"Yes") -> 0
B9: # | C9: Name | D9: Adult / Kid | E9: RSVP | F9: Diet | G9: Allergies / notes | H9: Bringing | I9: Table / seat
B10: 1 | C10: Anna (host) | D10: Adult | E10: Yes | F10: None | H10: Turkey | I10: Head
B11: 2 | C11: Mark | D11: Adult | E11: Yes | F11: Vegetarian | G11: Allergic to walnuts | H11: Wine | I11: T1
B12: 3 | C12: Lily | D12: Kid | E12: Maybe | F12: None | I12: Kids' table
B13: 4
B14: 5
B15: 6
B16: 7
B17: 8
B18: 9
B19: 10
B20: 11
B21: 12
B22: 13
B23: 14
B24: 15
... B69: 60

Sheet Food
B2: Food Calculator
B3: Portions per ADULT for a sit-down holiday dinner with several dishes. Kids, appetite and leftovers are applied automatically.
B5: Guests | C5: =Setup!$C$26&" adults + "&Setup!$C$27&" kids" -> 10 adults + 2 kids
B6: Cooking for | C6: =TEXT(Setup!$C$31,"0.0")&" adult portions" -> 13.8 adult portions
B8: Course | C8: Item | D8: Include? | E8: Per adult | F8: Unit | G8: Total needed | H8: Metric | J8: Imperial | L8: Tip
B9: Main | C9: Whole turkey (bone-in, raw weight) | D9: Yes | E9: 550 | F9: g | G9: =IF(OR(D9<>"Yes",E9=""),0,IF(OR(F9="g",F9="ml"),E9*Setup!$C$31,ROUNDUP(E9*Setup!$C$31,0))) -> 7562.5 | H9: =IF(OR(F9="g",F9="ml"),G9/1000,G9) -> 7.5625 | I9: =IF(F9="g","kg",IF(F9="ml","L",F9)) -> kg | J9: =IF(F9="g",G9/453.6,IF(F9="ml",G9/946.4,G9)) -> 16.672178 | K9: =IF(F9="g","lb",IF(F9="ml","qt",F9)) -> lb | L9: About 1¼ lb per person bone-in. Cook to 165°F / 74°C.
B10: Main | C10: Ham (bone-in) | D10: No | E10: 250 | F10: g | G10: =IF(OR(D10<>"Yes",E10=""),0,IF(OR(F10="g",F10="ml"),E10*Setup!$C$31,ROUNDUP(E10*Setup!$C$31,0))) -> 0 | H10: =IF(OR(F10="g",F10="ml"),G10/1000,G10) -> 0 | I10: =IF(F10="g","kg",IF(F10="ml","L",F10)) -> kg | J10: =IF(F10="g",G10/453.6,IF(F10="ml",G10/946.4,G10)) -> 0 | K10: =IF(F10="g","lb",IF(F10="ml","qt",F10)) -> lb | L10: Use 150 g if also serving turkey.
B11: Main | C11: Roast beef / prime rib (boneless) | D11: No | E11: 200 | F11: g | G11: =IF(OR(D11<>"Yes",E11=""),0,IF(OR(F11="g",F11="ml"),E11*Setup!$C$31,ROUNDUP(E11*Setup!$C$31,0))) -> 0 | H11: =IF(OR(F11="g",F11="ml"),G11/1000,G11) -> 0 | I11: =IF(F11="g","kg",IF(F11="ml","L",F11)) -> kg | J11: =IF(F11="g",G11/453.6,IF(F11="ml",G11/946.4,G11)) -> 0 | K11: =IF(F11="g","lb",IF(F11="ml","qt",F11)) -> lb | L11: Raw weight; shrinks ~25% when cooked.
B12: Main | C12: Whole chicken (raw) | D12: No | E12: 450 | F12: g | G12: =IF(OR(D12<>"Yes",E12=""),0,IF(OR(F12="g",F12="ml"),E12*Setup!$C$31,ROUNDUP(E12*Setup!$C$31,0))) -> 0 | H12: =IF(OR(F12="g",F12="ml"),G12/1000,G12) -> 0 | I12: =IF(F12="g","kg",IF(F12="ml","L",F12)) -> kg | J12: =IF(F12="g",G12/453.6,IF(F12="ml",G12/946.4,G12)) -> 0 | K12: =IF(F12="g","lb",IF(F12="ml","qt",F12)) -> lb
B13: Main | C13: Salmon / fish fillet | D13: No | E13: 170 | F13: g | G13: =IF(OR(D13<>"Yes",E13=""),0,IF(OR(F13="g",F13="ml"),E13*Setup!$C$31,ROUNDUP(E13*Setup!$C$31,0))) -> 0 | H13: =IF(OR(F13="g",F13="ml"),G13/1000,G13) -> 0 | I13: =IF(F13="g","kg",IF(F13="ml","L",F13)) -> kg | J13: =IF(F13="g",G13/453.6,IF(F13="ml",G13/946.4,G13)) -> 0 | K13: =IF(F13="g","lb",IF(F13="ml","qt",F13)) -> lb
B14: Main | C14: Vegetarian main (e.g. nut roast) | D14: No | E14: 200 | F14: g | G14: =IF(OR(D14<>"Yes",E14=""),0,IF(OR(F14="g",F14="ml"),E14*Setup!$C$31,ROUNDUP(E14*Setup!$C$31,0))) -> 0 | H14: =IF(OR(F14="g",F14="ml"),G14/1000,G14) -> 0 | I14: =IF(F14="g","kg",IF(F14="ml","L",F14)) -> kg | J14: =IF(F14="g",G14/453.6,IF(F14="ml",G14/946.4,G14)) -> 0 | K14: =IF(F14="g","lb",IF(F14="ml","qt",F14)) -> lb | L14: Tip: set per adult so it covers only veggie guests.
B15: Side | C15: Potatoes (mashed or roasted, raw) | D15: Yes | E15: 200 | F15: g | G15: =IF(OR(D15<>"Yes",E15=""),0,IF(OR(F15="g",F15="ml"),E15*Setup!$C$31,ROUNDUP(E15*Setup!$C$31,0))) -> 2750 | H15: =IF(OR(F15="g",F15="ml"),G15/1000,G15) -> 2.75 | I15: =IF(F15="g","kg",IF(F15="ml","L",F15)) -> kg | J15: =IF(F15="g",G15/453.6,IF(F15="ml",G15/946.4,G15)) -> 6.0626102 | K15: =IF(F15="g","lb",IF(F15="ml","qt",F15)) -> lb | L15: Most popular side — people take seconds.
B16: Side | C16: Stuffing / dressing (bread cubes) | D16: Yes | E16: 60 | F16: g | G16: =IF(OR(D16<>"Yes",E16=""),0,IF(OR(F16="g",F16="ml"),E16*Setup!$C$31,ROUNDUP(E16*Setup!$C$31,0))) -> 825 | H16: =IF(OR(F16="g",F16="ml"),G16/1000,G16) -> 0.825 | I16: =IF(F16="g","kg",IF(F16="ml","L",F16)) -> kg | J16: =IF(F16="g",G16/453.6,IF(F16="ml",G16/946.4,G16)) -> 1.8187831 | K16: =IF(F16="g","lb",IF(F16="ml","qt",F16)) -> lb | L16: Dry bread weight; ~1 cup prepared per person.
B17: Side | C17: Vegetable side #1 (green beans) | D17: Yes | E17: 120 | F17: g | G17: =IF(OR(D17<>"Yes",E17=""),0,IF(OR(F17="g",F17="ml"),E17*Setup!$C$31,ROUNDUP(E17*Setup!$C$31,0))) -> 1650 | H17: =IF(OR(F17="g",F17="ml"),G17/1000,G17) -> 1.65 | I17: =IF(F17="g","kg",IF(F17="ml","L",F17)) -> kg | J17: =IF(F17="g",G17/453.6,IF(F17="ml",G17/946.4,G17)) -> 3.6375661 | K17: =IF(F17="g","lb",IF(F17="ml","qt",F17)) -> lb
B18: Side | C18: Vegetable side #2 (Brussels sprouts / carrots) | D18: Yes | E18: 120 | F18: g | G18: =IF(OR(D18<>"Yes",E18=""),0,IF(OR(F18="g",F18="ml"),E18*Setup!$C$31,ROUNDUP(E18*Setup!$C$31,0))) -> 1650 | H18: =IF(OR(F18="g",F18="ml"),G18/1000,G18) -> 1.65 | I18: =IF(F18="g","kg",IF(F18="ml","L",F18)) -> kg | J18: =IF(F18="g",G18/453.6,IF(F18="ml",G18/946.4,G18)) -> 3.6375661 | K18: =IF(F18="g","lb",IF(F18="ml","qt",F18)) -> lb
B19: Side | C19: Sweet potatoes | D19: No | E19: 150 | F19: g | G19: =IF(OR(D19<>"Yes",E19=""),0,IF(OR(F19="g",F19="ml"),E19*Setup!$C$31,ROUNDUP(E19*Setup!$C$31,0))) -> 0 | H19: =IF(OR(F19="g",F19="ml"),G19/1000,G19) -> 0 | I19: =IF(F19="g","kg",IF(F19="ml","L",F19)) -> kg | J19: =IF(F19="g",G19/453.6,IF(F19="ml",G19/946.4,G19)) -> 0 | K19: =IF(F19="g","lb",IF(F19="ml","qt",F19)) -> lb
B20: Side | C20: Mac & cheese (dry pasta) | D20: No | E20: 50 | F20: g | G20: =IF(OR(D20<>"Yes",E20=""),0,IF(OR(F20="g",F20="ml"),E20*Setup!$C$31,ROUNDUP(E20*Setup!$C$31,0))) -> 0 | H20: =IF(OR(F20="g",F20="ml"),G20/1000,G20) -> 0 | I20: =IF(F20="g","kg",IF(F20="ml","L",F20)) -> kg | J20: =IF(F20="g",G20/453.6,IF(F20="ml",G20/946.4,G20)) -> 0 | K20: =IF(F20="g","lb",IF(F20="ml","qt",F20)) -> lb
B21: Side | C21: Salad greens | D21: No | E21: 40 | F21: g | G21: =IF(OR(D21<>"Yes",E21=""),0,IF(OR(F21="g",F21="ml"),E21*Setup!$C$31,ROUNDUP(E21*Setup!$C$31,0))) -> 0 | H21: =IF(OR(F21="g",F21="ml"),G21/1000,G21) -> 0 | I21: =IF(F21="g","kg",IF(F21="ml","L",F21)) -> kg | J21: =IF(F21="g",G21/453.6,IF(F21="ml",G21/946.4,G21)) -> 0 | K21: =IF(F21="g","lb",IF(F21="ml","qt",F21)) -> lb
B22: Side | C22: Gravy | D22: Yes | E22: 90 | F22: ml | G22: =IF(OR(D22<>"Yes",E22=""),0,IF(OR(F22="g",F22="ml"),E22*Setup!$C$31,ROUNDUP(E22*Setup!$C$31,0))) -> 1237.5 | H22: =IF(OR(F22="g",F22="ml"),G22/1000,G22) -> 1.2375 | I22: =IF(F22="g","kg",IF(F22="ml","L",F22)) -> L | J22: =IF(F22="g",G22/453.6,IF(F22="ml",G22/946.4,G22)) -> 1.3075866 | K22: =IF(F22="g","lb",IF(F22="ml","qt",F22)) -> qt | L22: About ⅓ cup per person.
B23: Side | C23: Cranberry sauce | D23: Yes | E23: 60 | F23: g | G23: =IF(OR(D23<>"Yes",E23=""),0,IF(OR(F23="g",F23="ml"),E23*Setup!$C$31,ROUNDUP(E23*Setup!$C$31,0))) -> 825 | H23: =IF(OR(F23="g",F23="ml"),G23/1000,G23) -> 0.825 | I23: =IF(F23="g","kg",IF(F23="ml","L",F23)) -> kg | J23: =IF(F23="g",G23/453.6,IF(F23="ml",G23/946.4,G23)) -> 1.8187831 | K23: =IF(F23="g","lb",IF(F23="ml","qt",F23)) -> lb
B24: Side | C24: Dinner rolls | D24: Yes | E24: 1.5 | F24: rolls | G24: =IF(OR(D24<>"Yes",E24=""),0,IF(OR(F24="g",F24="ml"),E24*Setup!$C$31,ROUNDUP(E24*Setup!$C$31,0))) -> 21 | H24: =IF(OR(F24="g",F24="ml"),G24/1000,G24) -> 21 | I24: =IF(F24="g","kg",IF(F24="ml","L",F24)) -> rolls | J24: =IF(F24="g",G24/453.6,IF(F24="ml",G24/946.4,G24)) -> 21 | K24: =IF(F24="g","lb",IF(F24="ml","qt",F24)) -> rolls
B25: Starter | C25: Cheese (for board) | D25: Yes | E25: 50 | F25: g | G25: =IF(OR(D25<>"Yes",E25=""),0,IF(OR(F25="g",F25="ml"),E25*Setup!$C$31,ROUNDUP(E25*Setup!$C$31,0))) -> 687.5 | H25: =IF(OR(F25="g",F25="ml"),G25/1000,G25) -> 0.6875 | I25: =IF(F25="g","kg",IF(F25="ml","L",F25)) -> kg | J25: =IF(F25="g",G25/453.6,IF(F25="ml",G25/946.4,G25)) -> 1.5156526 | K25: =IF(F25="g","lb",IF(F25="ml","qt",F25)) -> lb | L25: Use 100 g if the board IS the meal.
B26: Starter | C26: Cured meats | D26: No | E26: 40 | F26: g | G26: =IF(OR(D26<>"Yes",E26=""),0,IF(OR(F26="g",F26="ml"),E26*Setup!$C$31,ROUNDUP(E26*Setup!$C$31,0))) -> 0 | H26: =IF(OR(F26="g",F26="ml"),G26/1000,G26) -> 0 | I26: =IF(F26="g","kg",IF(F26="ml","L",F26)) -> kg | J26: =IF(F26="g",G26/453.6,IF(F26="ml",G26/946.4,G26)) -> 0 | K26: =IF(F26="g","lb",IF(F26="ml","qt",F26)) -> lb
B27: Starter | C27: Crackers / baguette | D27: Yes | E27: 40 | F27: g | G27: =IF(OR(D27<>"Yes",E27=""),0,IF(OR(F27="g",F27="ml"),E27*Setup!$C$31,ROUNDUP(E27*Setup!$C$31,0))) -> 550 | H27: =IF(OR(F27="g",F27="ml"),G27/1000,G27) -> 0.55 | I27: =IF(F27="g","kg",IF(F27="ml","L",F27)) -> kg | J27: =IF(F27="g",G27/453.6,IF(F27="ml",G27/946.4,G27)) -> 1.212522 | K27: =IF(F27="g","lb",IF(F27="ml","qt",F27)) -> lb
B28: Starter | C28: Dips + veggie sticks | D28: Yes | E28: 80 | F28: g | G28: =IF(OR(D28<>"Yes",E28=""),0,IF(OR(F28="g",F28="ml"),E28*Setup!$C$31,ROUNDUP(E28*Setup!$C$31,0))) -> 1100 | H28: =IF(OR(F28="g",F28="ml"),G28/1000,G28) -> 1.1 | I28: =IF(F28="g","kg",IF(F28="ml","L",F28)) -> kg | J28: =IF(F28="g",G28/453.6,IF(F28="ml",G28/946.4,G28)) -> 2.4250441 | K28: =IF(F28="g","lb",IF(F28="ml","qt",F28)) -> lb
B29: Starter | C29: Nuts / olives / snacks | D29: No | E29: 30 | F29: g | G29: =IF(OR(D29<>"Yes",E29=""),0,IF(OR(F29="g",F29="ml"),E29*Setup!$C$31,ROUNDUP(E29*Setup!$C$31,0))) -> 0 | H29: =IF(OR(F29="g",F29="ml"),G29/1000,G29) -> 0 | I29: =IF(F29="g","kg",IF(F29="ml","L",F29)) -> kg | J29: =IF(F29="g",G29/453.6,IF(F29="ml",G29/946.4,G29)) -> 0 | K29: =IF(F29="g","lb",IF(F29="ml","qt",F29)) -> lb
B30: Dessert | C30: Pies (8 slices each) | D30: Yes | E30: 0.16 | F30: pies | G30: =IF(OR(D30<>"Yes",E30=""),0,IF(OR(F30="g",F30="ml"),E30*Setup!$C$31,ROUNDUP(E30*Setup!$C$31,0))) -> 3 | H30: =IF(OR(F30="g",F30="ml"),G30/1000,G30) -> 3 | I30: =IF(F30="g","kg",IF(F30="ml","L",F30)) -> pies | J30: =IF(F30="g",G30/453.6,IF(F30="ml",G30/946.4,G30)) -> 3 | K30: =IF(F30="g","lb",IF(F30="ml","qt",F30)) -> pies | L30: 1¼ slices per person — someone always wants a second piece.
B31: Dessert | C31: Cake (12 slices) | D31: No | E31: 0.1 | F31: cakes | G31: =IF(OR(D31<>"Yes",E31=""),0,IF(OR(F31="g",F31="ml"),E31*Setup!$C$31,ROUNDUP(E31*Setup!$C$31,0))) -> 0 | H31: =IF(OR(F31="g",F31="ml"),G31/1000,G31) -> 0 | I31: =IF(F31="g","kg",IF(F31="ml","L",F31)) -> cakes | J31: =IF(F31="g",G31/453.6,IF(F31="ml",G31/946.4,G31)) -> 0 | K31: =IF(F31="g","lb",IF(F31="ml","qt",F31)) -> cakes
B32: Dessert | C32: Whipped cream / ice cream | D32: Yes | E32: 60 | F32: ml | G32: =IF(OR(D32<>"Yes",E32=""),0,IF(OR(F32="g",F32="ml"),E32*Setup!$C$31,ROUNDUP(E32*Setup!$C$31,0))) -> 825 | H32: =IF(OR(F32="g",F32="ml"),G32/1000,G32) -> 0.825 | I32: =IF(F32="g","kg",IF(F32="ml","L",F32)) -> L | J32: =IF(F32="g",G32/453.6,IF(F32="ml",G32/946.4,G32)) -> 0.87172443 | K32: =IF(F32="g","lb",IF(F32="ml","qt",F32)) -> qt
B33: Dessert | C33: Coffee (ground) | D33: Yes | E33: 10 | F33: g | G33: =IF(OR(D33<>"Yes",E33=""),0,IF(OR(F33="g",F33="ml"),E33*Setup!$C$31,ROUNDUP(E33*Setup!$C$31,0))) -> 137.5 | H33: =IF(OR(F33="g",F33="ml"),G33/1000,G33) -> 0.1375 | I33: =IF(F33="g","kg",IF(F33="ml","L",F33)) -> kg | J33: =IF(F33="g",G33/453.6,IF(F33="ml",G33/946.4,G33)) -> 0.30313051 | K33: =IF(F33="g","lb",IF(F33="ml","qt",F33)) -> lb | L33: About 1 cup per adult.
B34: Custom | D34: No | F34: g | G34: =IF(OR(D34<>"Yes",E34=""),0,IF(OR(F34="g",F34="ml"),E34*Setup!$C$31,ROUNDUP(E34*Setup!$C$31,0))) -> 0 | H34: =IF(OR(F34="g",F34="ml"),G34/1000,G34) -> 0 | I34: =IF(F34="g","kg",IF(F34="ml","L",F34)) -> kg | J34: =IF(F34="g",G34/453.6,IF(F34="ml",G34/946.4,G34)) -> 0 | K34: =IF(F34="g","lb",IF(F34="ml","qt",F34)) -> lb | L34: Add your own dish: name, per adult, unit (g / ml / any word for pieces).
B35: Custom | D35: No | F35: g | G35: =IF(OR(D35<>"Yes",E35=""),0,IF(OR(F35="g",F35="ml"),E35*Setup!$C$31,ROUNDUP(E35*Setup!$C$31,0))) -> 0 | H35: =IF(OR(F35="g",F35="ml"),G35/1000,G35) -> 0 | I35: =IF(F35="g","kg",IF(F35="ml","L",F35)) -> kg | J35: =IF(F35="g",G35/453.6,IF(F35="ml",G35/946.4,G35)) -> 0 | K35: =IF(F35="g","lb",IF(F35="ml","qt",F35)) -> lb
B36: Custom | D36: No | F36: g | G36: =IF(OR(D36<>"Yes",E36=""),0,IF(OR(F36="g",F36="ml"),E36*Setup!$C$31,ROUNDUP(E36*Setup!$C$31,0))) -> 0 | H36: =IF(OR(F36="g",F36="ml"),G36/1000,G36) -> 0 | I36: =IF(F36="g","kg",IF(F36="ml","L",F36)) -> kg | J36: =IF(F36="g",G36/453.6,IF(F36="ml",G36/946.4,G36)) -> 0 | K36: =IF(F36="g","lb",IF(F36="ml","qt",F36)) -> lb
B37: Custom | D37: No | F37: g | G37: =IF(OR(D37<>"Yes",E37=""),0,IF(OR(F37="g",F37="ml"),E37*Setup!$C$31,ROUNDUP(E37*Setup!$C$31,0))) -> 0 | H37: =IF(OR(F37="g",F37="ml"),G37/1000,G37) -> 0 | I37: =IF(F37="g","kg",IF(F37="ml","L",F37)) -> kg | J37: =IF(F37="g",G37/453.6,IF(F37="ml",G37/946.4,G37)) -> 0 | K37: =IF(F37="g","lb",IF(F37="ml","qt",F37)) -> lb
C39: Total food to buy (by weight) | H39: =SUMIF(F9:F37,"g",G9:G37)/1000 -> 17.7375 | I39: kg | J39: =H39*2.2046 -> 39.104093 | K39: lb
C41: Portion sizes are standard catering rules of thumb for a multi-dish holiday meal. Adjust 'Per adult' to match your crowd.

Sheet Drinks
B2: Drinks Calculator
B3: Based on the classic host rule: 2 drinks in the first hour, then 1 drink per hour per guest.
B5: Assumptions (gold = editable)
B6: Drinks per drinker — first hour | C6: 2 | D6: The classic party rule of thumb.
B7: Drinks per drinker — each extra hour | C7: 1
B8: Share of drinks that are wine | C8: 0.5 | D8: Wine + beer + cocktails should add up to 100%.
B9: Share that is beer / cider | C9: 0.3
B10: Share that is cocktails / spirits | C10: 0.2
B11: Glasses per bottle of wine (750 ml) | C11: 5 | D11: 5 glasses of 150 ml / 5 oz.
B12: Drinks per bottle of spirits (750 ml) | C12: 16 | D12: About 1.5 oz / 45 ml per drink.
B13: Mixer per cocktail (L) | C13: 0.15 | D13: About 5 oz.
B14: Soft drink serving (L) | C14: 0.25 | D14: About 8 oz glass.
B15: Water per guest (L) | C15: 0.5 | D15: Still + sparkling for the table.
B16: Ice per guest (kg) | C16: 0.5 | D16: About 1 lb per guest. Double it on a hot day.
B17: Check: shares add up to | C17: =$C$8+$C$9+$C$10 -> 1
B19: What to buy
B20: Item | C20: Metric | E20: Imperial | G20: How it's calculated
B21: Alcoholic drinks in total | C21: =ROUND((Setup!$C$26*Setup!$C$16*($C$6+MAX(Setup!$C$9-1,0)*$C$7)),0) -> 45 | D21: drinks | E21: =C21 -> 45 | F21: drinks | G21: Adults who drink × drinks per hour × hours.
B22: Wine | C22: =ROUNDUP((Setup!$C$26*Setup!$C$16*($C$6+MAX(Setup!$C$9-1,0)*$C$7))*$C$8/$C$11,0) -> 5 | D22: bottles | E22: =C22 -> 5 | F22: bottles | G22: 750 ml bottles.
B23: Beer / cider | C23: =ROUNDUP((Setup!$C$26*Setup!$C$16*($C$6+MAX(Setup!$C$9-1,0)*$C$7))*$C$9,0) -> 14 | D23: bottles | E23: =C23 -> 14 | F23: bottles | G23: 330 ml / 12 oz bottles or cans.
B24: Spirits for cocktails | C24: =ROUNDUP((Setup!$C$26*Setup!$C$16*($C$6+MAX(Setup!$C$9-1,0)*$C$7))*$C$10/$C$12,0) -> 1 | D24: bottles | E24: =C24 -> 1 | F24: bottles | G24: 750 ml bottles.
B25: Mixers (tonic, soda, juice) | C25: =ROUNDUP((Setup!$C$26*Setup!$C$16*($C$6+MAX(Setup!$C$9-1,0)*$C$7))*$C$10*$C$13,1) -> 1.4 | D25: L | E25: =C25*1.0567 -> 1.47938 | F25: qt
B26: Soft drinks & juice | C26: =ROUNDUP((Setup!$C$26*(1-Setup!$C$16)+Setup!$C$27)*($C$6+MAX(Setup!$C$9-1,0)*$C$7)*$C$14+Setup!$C$26*Setup!$C$16*$C$14,1) -> 8.7 | D26: L | E26: =C26*1.0567 -> 9.19329 | F26: qt | G26: Kids + non-drinkers drink at the same pace; drinkers get one glass too.
B27: → in 2-liter bottles | C27: =ROUNDUP(C26/2,0) -> 5 | D27: bottles | E27: =C27 -> 5 | F27: bottles
B28: Water | C28: =ROUNDUP((Setup!$C$26+Setup!$C$27)*$C$15,1) -> 6 | D28: L | E28: =C28*1.0567 -> 6.3402 | F28: qt
B29: Ice | C29: =ROUNDUP((Setup!$C$26+Setup!$C$27)*$C$16,1) -> 6 | D29: kg | E29: =C29*2.2046 -> 13.2276 | F29: lb

Sheet Shopping
B2: Shopping List
B3: Quantities fill in automatically. Add your store's prices to see the cost. Tick items as you buy them.
B5: Units | C5: =Setup!$C$15 -> Imperial (lb) | E5: Still to buy | F5: =COUNTIFS(H9:H56,"<>✓",D9:D56,">0") -> 24
B6: Est. total | C6: =SUM(G9:G56) -> 308.39327 | E6: Bought | F6: =COUNTIF(H9:H56,"✓") -> 0
B8: Category | C8: Item | D8: Qty | E8: Unit | F8: Price / unit | G8: Est. cost | H8: Bought?
B9: Food | C9: =IF(Food!C9="","",Food!C9) -> Whole turkey (bone-in, raw weight) | D9: =IF(Setup!$C$32=1,Food!H9,Food!J9) -> 16.672178 | E9: =IF(Setup!$C$32=1,Food!I9,Food!K9) -> lb | F9: 1.99 | G9: =D9*F9 -> 33.177634
B10: Food | C10: =IF(Food!C10="","",Food!C10) -> Ham (bone-in) | D10: =IF(Setup!$C$32=1,Food!H10,Food!J10) -> 0 | E10: =IF(Setup!$C$32=1,Food!I10,Food!K10) -> lb | G10: =D10*F10 -> 0
B11: Food | C11: =IF(Food!C11="","",Food!C11) -> Roast beef / prime rib (boneless) | D11: =IF(Setup!$C$32=1,Food!H11,Food!J11) -> 0 | E11: =IF(Setup!$C$32=1,Food!I11,Food!K11) -> lb | G11: =D11*F11 -> 0
B12: Food | C12: =IF(Food!C12="","",Food!C12) -> Whole chicken (raw) | D12: =IF(Setup!$C$32=1,Food!H12,Food!J12) -> 0 | E12: =IF(Setup!$C$32=1,Food!I12,Food!K12) -> lb | G12: =D12*F12 -> 0
B13: Food | C13: =IF(Food!C13="","",Food!C13) -> Salmon / fish fillet | D13: =IF(Setup!$C$32=1,Food!H13,Food!J13) -> 0 | E13: =IF(Setup!$C$32=1,Food!I13,Food!K13) -> lb | G13: =D13*F13 -> 0
B14: Food | C14: =IF(Food!C14="","",Food!C14) -> Vegetarian main (e.g. nut roast) | D14: =IF(Setup!$C$32=1,Food!H14,Food!J14) -> 0 | E14: =IF(Setup!$C$32=1,Food!I14,Food!K14) -> lb | G14: =D14*F14 -> 0
B15: Food | C15: =IF(Food!C15="","",Food!C15) -> Potatoes (mashed or roasted, raw) | D15: =IF(Setup!$C$32=1,Food!H15,Food!J15) -> 6.0626102 | E15: =IF(Setup!$C$32=1,Food!I15,Food!K15) -> lb | F15: 0.99 | G15: =D15*F15 -> 6.0019841
B16: Food | C16: =IF(Food!C16="","",Food!C16) -> Stuffing / dressing (bread cubes) | D16: =IF(Setup!$C$32=1,Food!H16,Food!J16) -> 1.8187831 | E16: =IF(Setup!$C$32=1,Food!I16,Food!K16) -> lb | F16: 3.5 | G16: =D16*F16 -> 6.3657407
B17: Food | C17: =IF(Food!C17="","",Food!C17) -> Vegetable side #1 (green beans) | D17: =IF(Setup!$C$32=1,Food!H17,Food!J17) -> 3.6375661 | E17: =IF(Setup!$C$32=1,Food!I17,Food!K17) -> lb | F17: 2.49 | G17: =D17*F17 -> 9.0575397
B18: Food | C18: =IF(Food!C18="","",Food!C18) -> Vegetable side #2 (Brussels sprouts / carrots) | D18: =IF(Setup!$C$32=1,Food!H18,Food!J18) -> 3.6375661 | E18: =IF(Setup!$C$32=1,Food!I18,Food!K18) -> lb | F18: 3.49 | G18: =D18*F18 -> 12.695106
B19: Food | C19: =IF(Food!C19="","",Food!C19) -> Sweet potatoes | D19: =IF(Setup!$C$32=1,Food!H19,Food!J19) -> 0 | E19: =IF(Setup!$C$32=1,Food!I19,Food!K19) -> lb | G19: =D19*F19 -> 0
B20: Food | C20: =IF(Food!C20="","",Food!C20) -> Mac & cheese (dry pasta) | D20: =IF(Setup!$C$32=1,Food!H20,Food!J20) -> 0 | E20: =IF(Setup!$C$32=1,Food!I20,Food!K20) -> lb | G20: =D20*F20 -> 0
B21: Food | C21: =IF(Food!C21="","",Food!C21) -> Salad greens | D21: =IF(Setup!$C$32=1,Food!H21,Food!J21) -> 0 | E21: =IF(Setup!$C$32=1,Food!I21,Food!K21) -> lb | G21: =D21*F21 -> 0
B22: Food | C22: =IF(Food!C22="","",Food!C22) -> Gravy | D22: =IF(Setup!$C$32=1,Food!H22,Food!J22) -> 1.3075866 | E22: =IF(Setup!$C$32=1,Food!I22,Food!K22) -> qt | F22: 2 | G22: =D22*F22 -> 2.6151733
B23: Food | C23: =IF(Food!C23="","",Food!C23) -> Cranberry sauce | D23: =IF(Setup!$C$32=1,Food!H23,Food!J23) -> 1.8187831 | E23: =IF(Setup!$C$32=1,Food!I23,Food!K23) -> lb | F23: 3.99 | G23: =D23*F23 -> 7.2569444
B24: Food | C24: =IF(Food!C24="","",Food!C24) -> Dinner rolls | D24: =IF(Setup!$C$32=1,Food!H24,Food!J24) -> 21 | E24: =IF(Setup!$C$32=1,Food!I24,Food!K24) -> rolls | F24: 0.5 | G24: =D24*F24 -> 10.5
B25: Food | C25: =IF(Food!C25="","",Food!C25) -> Cheese (for board) | D25: =IF(Setup!$C$32=1,Food!H25,Food!J25) -> 1.5156526 | E25: =IF(Setup!$C$32=1,Food!I25,Food!K25) -> lb | F25: 9.99 | G25: =D25*F25 -> 15.141369
B26: Food | C26: =IF(Food!C26="","",Food!C26) -> Cured meats | D26: =IF(Setup!$C$32=1,Food!H26,Food!J26) -> 0 | E26: =IF(Setup!$C$32=1,Food!I26,Food!K26) -> lb | G26: =D26*F26 -> 0
B27: Food | C27: =IF(Food!C27="","",Food!C27) -> Crackers / baguette | D27: =IF(Setup!$C$32=1,Food!H27,Food!J27) -> 1.212522 | E27: =IF(Setup!$C$32=1,Food!I27,Food!K27) -> lb | F27: 4.99 | G27: =D27*F27 -> 6.050485
B28: Food | C28: =IF(Food!C28="","",Food!C28) -> Dips + veggie sticks | D28: =IF(Setup!$C$32=1,Food!H28,Food!J28) -> 2.4250441 | E28: =IF(Setup!$C$32=1,Food!I28,Food!K28) -> lb | F28: 4.99 | G28: =D28*F28 -> 12.10097
B29: Food | C29: =IF(Food!C29="","",Food!C29) -> Nuts / olives / snacks | D29: =IF(Setup!$C$32=1,Food!H29,Food!J29) -> 0 | E29: =IF(Setup!$C$32=1,Food!I29,Food!K29) -> lb | G29: =D29*F29 -> 0
B30: Food | C30: =IF(Food!C30="","",Food!C30) -> Pies (8 slices each) | D30: =IF(Setup!$C$32=1,Food!H30,Food!J30) -> 3 | E30: =IF(Setup!$C$32=1,Food!I30,Food!K30) -> pies | F30: 12.99 | G30: =D30*F30 -> 38.97
B31: Food | C31: =IF(Food!C31="","",Food!C31) -> Cake (12 slices) | D31: =IF(Setup!$C$32=1,Food!H31,Food!J31) -> 0 | E31: =IF(Setup!$C$32=1,Food!I31,Food!K31) -> cakes | G31: =D31*F31 -> 0
B32: Food | C32: =IF(Food!C32="","",Food!C32) -> Whipped cream / ice cream | D32: =IF(Setup!$C$32=1,Food!H32,Food!J32) -> 0.87172443 | E32: =IF(Setup!$C$32=1,Food!I32,Food!K32) -> qt | F32: 5 | G32: =D32*F32 -> 4.3586221
B33: Food | C33: =IF(Food!C33="","",Food!C33) -> Coffee (ground) | D33: =IF(Setup!$C$32=1,Food!H33,Food!J33) -> 0.30313051 | E33: =IF(Setup!$C$32=1,Food!I33,Food!K33) -> lb | F33: 8.99 | G33: =D33*F33 -> 2.7251433
B34: Food | C34: =IF(Food!C34="","",Food!C34) | D34: =IF(Setup!$C$32=1,Food!H34,Food!J34) -> 0 | E34: =IF(Setup!$C$32=1,Food!I34,Food!K34) -> lb | G34: =D34*F34 -> 0
B35: Food | C35: =IF(Food!C35="","",Food!C35) | D35: =IF(Setup!$C$32=1,Food!H35,Food!J35) -> 0 | E35: =IF(Setup!$C$32=1,Food!I35,Food!K35) -> lb | G35: =D35*F35 -> 0
B36: Food | C36: =IF(Food!C36="","",Food!C36) | D36: =IF(Setup!$C$32=1,Food!H36,Food!J36) -> 0 | E36: =IF(Setup!$C$32=1,Food!I36,Food!K36) -> lb | G36: =D36*F36 -> 0
B37: Food | C37: =IF(Food!C37="","",Food!C37) | D37: =IF(Setup!$C$32=1,Food!H37,Food!J37) -> 0 | E37: =IF(Setup!$C$32=1,Food!I37,Food!K37) -> lb | G37: =D37*F37 -> 0
B38: Drinks | C38: Wine | D38: =IF(Setup!$C$32=1,Drinks!C22,Drinks!E22) -> 5 | E38: =IF(Setup!$C$32=1,Drinks!D22,Drinks!F22) -> bottles | F38: 12 | G38: =D38*F38 -> 60
B39: Drinks | C39: Beer / cider | D39: =IF(Setup!$C$32=1,Drinks!C23,Drinks!E23) -> 14 | E39: =IF(Setup!$C$32=1,Drinks!D23,Drinks!F23) -> bottles | F39: 1.5 | G39: =D39*F39 -> 21
B40: Drinks | C40: Spirits for cocktails | D40: =IF(Setup!$C$32=1,Drinks!C24,Drinks!E24) -> 1 | E40: =IF(Setup!$C$32=1,Drinks!D24,Drinks!F24) -> bottles | F40: 22 | G40: =D40*F40 -> 22
B41: Drinks | C41: Mixers (tonic, soda, juice) | D41: =IF(Setup!$C$32=1,Drinks!C25,Drinks!E25) -> 1.47938 | E41: =IF(Setup!$C$32=1,Drinks!D25,Drinks!F25) -> qt | G41: =D41*F41 -> 0
B42: Drinks | C42: Soft drinks & juice (2-liter bottles) | D42: =IF(Setup!$C$32=1,Drinks!C27,Drinks!E27) -> 5 | E42: =IF(Setup!$C$32=1,Drinks!D27,Drinks!F27) -> bottles | F42: 2.29 | G42: =D42*F42 -> 11.45
B43: Drinks | C43: Water | D43: =IF(Setup!$C$32=1,Drinks!C28,Drinks!E28) -> 6.3402 | E43: =IF(Setup!$C$32=1,Drinks!D28,Drinks!F28) -> qt | G43: =D43*F43 -> 0
...

Sheet Budget
B2: Budget
B3: Planned costs come from the Shopping List. Type what you actually spent in the gold column.
B5: Category | C5: Planned | D5: Actual | E5: Difference | F5: Notes
B6: Food | C6: =SUMIF(Shopping!$B$9:$B$56,"Food",Shopping!$G$9:$G$56) -> 167.01671 | E6: =IF(D6="","",C6-D6) | F6: From Shopping List
B7: Drinks | C7: =SUMIF(Shopping!$B$9:$B$56,"Drinks",Shopping!$G$9:$G$56) -> 122.38656 | E7: =IF(D7="","",C7-D7) | F7: From Shopping List
B8: Other groceries | C8: =SUMIF(Shopping!$B$9:$B$56,"Other",Shopping!$G$9:$G$56) -> 18.99 | E8: =IF(D8="","",C8-D8) | F8: From Shopping List
B9: Decor & flowers | C9: 40 | E9: =IF(D9="","",C9-D9)
B10: Tableware & linens | C10: 30 | E10: =IF(D10="","",C10-D10)
B11: Gifts / party favors | C11: 0 | E11: =IF(D11="","",C11-D11)
B12: Miscellaneous | C12: 25 | E12: =IF(D12="","",C12-D12)
B13: TOTAL | C13: =SUM(C6:C12) -> 403.39327 | D13: =SUM(D6:D12) -> 0 | E13: =IF(D13=0,"",C13-D13)
B15: Summary
B16: Your budget | C16: =Setup!$C$17 -> 600
B17: Planned spend | C17: =C13 -> 403.39327
B18: Left over (planned) | C18: =C16-C17 -> 196.60673
B19: Cost per guest (planned) | C19: =IF(Setup!$C$28=0,0,C17/Setup!$C$28) -> 33.616106
B20: Actual spend so far | C20: =D13 -> 0

Sheet Timeline
B2: Cooking Timeline
B3: Counts backwards from the time dinner is served. Turkey time is calculated from its weight.
B5: Dinner is served at | C5: =Setup!$C$8 -> 0.70833333
B6: Turkey weight (lb) | C6: =Food!$J$9 -> 16.672178
B8: Dish | C8: Where | D8: Prep (min) | E8: Cook (min) | F8: Rest / hold (min) | G8: Start prep | H8: Start cooking | I8: Done cooking | J8: Notes
B9: Turkey | C9: Oven | D9: 30 | E9: =ROUND(Food!$J$9*15,0) -> 250 | F9: 40 | G9: =IF(B9="","",MOD($C$5-(D9+E9+F9)/1440,1)) -> 0.48611111 | H9: =IF(OR(B9="",E9=0),"",MOD($C$5-(E9+F9)/1440,1)) -> 0.50694444 | I9: =IF(OR(B9="",E9=0),"",MOD($C$5-F9/1440,1)) -> 0.68055556 | J9: ~15 min per lb at 325°F / 165°C (unstuffed). Check 165°F / 74°C in the thigh.
B10: Stuffing / dressing | C10: Oven | D10: 20 | E10: 45 | F10: 10 | G10: =IF(B10="","",MOD($C$5-(D10+E10+F10)/1440,1)) -> 0.65625 | H10: =IF(OR(B10="",E10=0),"",MOD($C$5-(E10+F10)/1440,1)) -> 0.67013889 | I10: =IF(OR(B10="",E10=0),"",MOD($C$5-F10/1440,1)) -> 0.70138889 | J10: Bake while the turkey rests.
B11: Sweet potatoes / casserole | C11: Oven | D11: 20 | E11: 35 | F11: 5 | G11: =IF(B11="","",MOD($C$5-(D11+E11+F11)/1440,1)) -> 0.66666667 | H11: =IF(OR(B11="",E11=0),"",MOD($C$5-(E11+F11)/1440,1)) -> 0.68055556 | I11: =IF(OR(B11="",E11=0),"",MOD($C$5-F11/1440,1)) -> 0.70486111
B12: Roasted vegetables | C12: Oven | D12: 15 | E12: 30 | F12: 5 | G12: =IF(B12="","",MOD($C$5-(D12+E12+F12)/1440,1)) -> 0.67361111 | H12: =IF(OR(B12="",E12=0),"",MOD($C$5-(E12+F12)/1440,1)) -> 0.68402778 | I12: =IF(OR(B12="",E12=0),"",MOD($C$5-F12/1440,1)) -> 0.70486111
B13: Mashed potatoes | C13: Stove | D13: 20 | E13: 25 | F13: 0 | G13: =IF(B13="","",MOD($C$5-(D13+E13+F13)/1440,1)) -> 0.67708333 | H13: =IF(OR(B13="",E13=0),"",MOD($C$5-(E13+F13)/1440,1)) -> 0.69097222 | I13: =IF(OR(B13="",E13=0),"",MOD($C$5-F13/1440,1)) -> 0.70833333 | J13: Keep warm in a slow cooker.
B14: Green beans | C14: Stove | D14: 10 | E14: 12 | F14: 0 | G14: =IF(B14="","",MOD($C$5-(D14+E14+F14)/1440,1)) -> 0.69305556 | H14: =IF(OR(B14="",E14=0),"",MOD($C$5-(E14+F14)/1440,1)) -> 0.7 | I14: =IF(OR(B14="",E14=0),"",MOD($C$5-F14/1440,1)) -> 0.70833333
B15: Gravy | C15: Stove | D15: 5 | E15: 15 | F15: 0 | G15: =IF(B15="","",MOD($C$5-(D15+E15+F15)/1440,1)) -> 0.69444444 | H15: =IF(OR(B15="",E15=0),"",MOD($C$5-(E15+F15)/1440,1)) -> 0.69791667 | I15: =IF(OR(B15="",E15=0),"",MOD($C$5-F15/1440,1)) -> 0.70833333 | J15: Use the turkey drippings.
B16: Dinner rolls | C16: Oven | D16: 5 | E16: 12 | F16: 0 | G16: =IF(B16="","",MOD($C$5-(D16+E16+F16)/1440,1)) -> 0.69652778 | H16: =IF(OR(B16="",E16=0),"",MOD($C$5-(E16+F16)/1440,1)) -> 0.7 | I16: =IF(OR(B16="",E16=0),"",MOD($C$5-F16/1440,1)) -> 0.70833333 | J16: Warm up when the turkey comes out.
B17: Appetizer board | C17: Counter | D17: 25 | E17: 0 | F17: 90 | G17: =IF(B17="","",MOD($C$5-(D17+E17+F17)/1440,1)) -> 0.62847222 | H17: =IF(OR(B17="",E17=0),"",MOD($C$5-(E17+F17)/1440,1)) | I17: =IF(OR(B17="",E17=0),"",MOD($C$5-F17/1440,1)) | J17: Ready when guests arrive (90 min before dinner).
B18: Pies | C18: Oven | D18: 30 | E18: 55 | F18: 240 | G18: =IF(B18="","",MOD($C$5-(D18+E18+F18)/1440,1)) -> 0.48263889 | H18: =IF(OR(B18="",E18=0),"",MOD($C$5-(E18+F18)/1440,1)) -> 0.50347222 | I18: =IF(OR(B18="",E18=0),"",MOD($C$5-F18/1440,1)) -> 0.54166667 | J18: Bake in the morning or the day before.
G19: =IF(B19="","",MOD($C$5-(D19+E19+F19)/1440,1)) | H19: =IF(OR(B19="",E19=0),"",MOD($C$5-(E19+F19)/1440,1)) | I19: =IF(OR(B19="",E19=0),"",MOD($C$5-F19/1440,1))
G20: =IF(B20="","",MOD($C$5-(D20+E20+F20)/1440,1)) | H20: =IF(OR(B20="",E20=0),"",MOD($C$5-(E20+F20)/1440,1)) | I20: =IF(OR(B20="",E20=0),"",MOD($C$5-F20/1440,1))
G21: =IF(B21="","",MOD($C$5-(D21+E21+F21)/1440,1)) | H21: =IF(OR(B21="",E21=0),"",MOD($C$5-(E21+F21)/1440,1)) | I21: =IF(OR(B21="",E21=0),"",MOD($C$5-F21/1440,1))
B23: Key dates
B24: Move turkey to the fridge to thaw | C24: =IF(Food!$J$9=0,"No turkey",Setup!$C$7-ROUNDUP(Food!$J$9/4,0)) -> 46347 | F24: 1 day in the fridge for every 4 lb (USDA guideline).
B25: Big shopping trip | C25: =Setup!$C$7-3 -> 46349 | F25: Buy fresh produce 1–2 days before.
B26: Bake pies, make cranberry sauce | C26: =Setup!$C$7-1 -> 46351
B27: Party day | C27: =Setup!$C$7 -> 46352

Sheet Checklist
B2: Host Checklist
B3: Pick a ✓ in the Done column as you go.
C4: =COUNTIF(D6:D33,"✓")&" of "&COUNTA(C6:C33)&" tasks done" -> 0 of 23 tasks done
B5: When | C5: Task | D5: Done
B6: 3 weeks before | C6: Set the date and time, send invitations
C7: Ask about diets and allergies (Guests tab)
C8: Decide the menu (Food tab: Include? = Yes)
C9: Order the turkey if buying fresh / heritage
B10: 2 weeks before | C10: Check you have enough chairs, plates, glasses, cutlery
C11: Plan the cooking timeline — does everything fit in the oven?
C12: Buy drinks and non-perishables
B13: 1 week before | C13: Confirm RSVPs and update guest count
C14: Plan seating and table layout
C15: Clean out the fridge to make room
B16: 3–4 days before | C16: Start thawing a frozen turkey (see Key dates)
C17: Big shopping trip (Shopping tab)
C18: Iron tablecloth and napkins
B19: Day before | C19: Bake pies and make cranberry sauce
C20: Chop vegetables, make stuffing base
C21: Set the table
C22: Chill drinks, buy ice
B23: Party day | C23: Follow the Cooking Timeline
C24: Set up appetizers and drinks station
C25: Light candles, put on music
C26: Enjoy your guests!
B27: After | C27: Pack leftovers for guests
C28: Note what ran out / was left for next year
